<?xml version="1.0"?>
<robot name="xarm6_robot">
  <!-- Materials -->
  <material name="White">
    <color rgba="1.0 1.0 1.0 1.0"/>
  </material>
  
  <material name="Silver">
    <color rgba="0.7 0.7 0.7 1.0"/>
  </material>

  <!-- Common macro for link inertial properties -->
  <macro name="common_link_inertial" params="link_inertial_params origin_rpy">
    <inertial>
      <origin xyz="${link_inertial_params['x']} ${link_inertial_params['y']} ${link_inertial_params['z']}" rpy="${origin_rpy}"/>
      <mass value="${link_inertial_params['mass']}"/>
      <inertia 
        ixx="${link_inertial_params['ixx']}" ixy="${link_inertial_params['ixy']}" ixz="${link_inertial_params['ixz']}"
        iyy="${link_inertial_params['iyy']}" iyz="${link_inertial_params['iyz']}" izz="${link_inertial_params['izz']}"/>
    </inertial>
  </macro>

  <!-- Common macro for link visual properties -->
  <macro name="common_link_visual" params="mesh_filename origin_xyz origin_rpy material_name">
    <visual>
      <origin xyz="${origin_xyz}" rpy="${origin_rpy}"/>
      <geometry>
        <mesh filename="package://xarm_description/meshes/${mesh_filename}.stl"/>
      </geometry>
      <material name="${material_name}"/>
    </visual>
  </macro>

  <!-- Common macro for link collision properties -->
  <macro name="common_link_collision" params="mesh_filename origin_xyz origin_rpy">
    <collision>
      <origin xyz="${origin_xyz}" rpy="${origin_rpy}"/>
      <geometry>
        <mesh filename="package://xarm_description/meshes/${mesh_filename}.stl"/>
      </geometry>
    </collision>
  </macro>

  <!-- Common macro for joint origin -->
  <macro name="common_joint_origin" params="joint_kinematic_params">
    <origin 
      xyz="${joint_kinematic_params['x']} ${joint_kinematic_params['y']} ${joint_kinematic_params['z']}" 
      rpy="${joint_kinematic_params['roll']} ${joint_kinematic_params['pitch']} ${joint_kinematic_params['yaw']}"/>
  </macro>

  <!-- Base Link -->
  <link name="link_base">
    <inertial>
      <origin xyz="0.0 0.0 0.09103" rpy="0 0 0" />
      <mass value="2.7" />
      <inertia
        ixx="0.00494875" ixy="-3.5E-06" ixz="1.25E-05"
        iyy="0.00494174" iyz="1.67E-06" izz="0.002219" />
    </inertial>
    <visual>
      <origin xyz="0 0 0" rpy="0 0 0"/>
      <geometry>
        <mesh filename="package://xarm_description/meshes/xarm6/visual/link_base.stl"/>
      </geometry>
      <material name="White"/>
    </visual>
    <collision>
      <origin xyz="0 0 0" rpy="0 0 0"/>
      <geometry>
        <mesh filename="package://xarm_description/meshes/xarm6/visual/link_base.stl"/>
      </geometry>
    </collision>
  </link>

  <!-- Link 1 -->
  <link name="link1">
    <inertial>
      <origin xyz="0 0 0" rpy="0 0 0" />
      <mass value="2.7" />
      <inertia
        ixx="0.01" ixy="0" ixz="0"
        iyy="0.01" iyz="0" izz="0.01" />
    </inertial>
    <visual>
      <origin xyz="0 0 0" rpy="0 0 0"/>
      <geometry>
        <mesh filename="package://xarm_description/meshes/xarm6/visual/link1.stl"/>
      </geometry>
      <material name="White"/>
    </visual>
    <collision>
      <origin xyz="0 0 0" rpy="0 0 0"/>
      <geometry>
        <mesh filename="package://xarm_description/meshes/xarm6/visual/link1.stl"/>
      </geometry>
    </collision>
  </link>

  <!-- Joint 1 -->
  <joint name="joint1" type="revolute">
    <parent link="link_base"/>
    <child link="link1"/>
    <origin xyz="0 0 0.267" rpy="0 0 0"/>
    <axis xyz="0 0 1"/>
    <limit lower="-6.28319" upper="6.28319" effort="50.0" velocity="3.14"/>
    <dynamics damping="1.0" friction="1.0"/>
  </joint>

  <!-- Link 2 -->
  <link name="link2">
    <inertial>
      <origin xyz="0 0 0" rpy="0 0 0" />
      <mass value="2.5" />
      <inertia
        ixx="0.01" ixy="0" ixz="0"
        iyy="0.01" iyz="0" izz="0.01" />
    </inertial>
    <visual>
      <origin xyz="0 0 0" rpy="0 0 0"/>
      <geometry>
        <mesh filename="package://xarm_description/meshes/xarm6/visual/link2.stl"/>
      </geometry>
      <material name="White"/>
    </visual>
    <collision>
      <origin xyz="0 0 0" rpy="0 0 0"/>
      <geometry>
        <mesh filename="package://xarm_description/meshes/xarm6/visual/link2.stl"/>
      </geometry>
    </collision>
  </link>

  <!-- Joint 2 -->
  <joint name="joint2" type="revolute">
    <parent link="link1"/>
    <child link="link2"/>
    <origin xyz="0 0 0" rpy="-1.5708 0 0" />
    <axis xyz="0 0 1"/>
    <limit lower="-2.059" upper="2.0944" effort="50.0" velocity="3.14"/>
    <dynamics damping="1.0" friction="1.0"/>
  </joint>

  <!-- Link 3 -->
  <link name="link3">
    <inertial>
      <origin xyz="0 0 0" rpy="0 0 0" />
      <mass value="2.0" />
      <inertia
        ixx="0.01" ixy="0" ixz="0"
        iyy="0.01" iyz="0" izz="0.01" />
    </inertial>
    <visual>
      <origin xyz="0 0 0" rpy="0 0 0"/>
      <geometry>
        <mesh filename="package://xarm_description/meshes/xarm6/visual/link3.stl"/>
      </geometry>
      <material name="White"/>
    </visual>
    <collision>
      <origin xyz="0 0 0" rpy="0 0 0"/>
      <geometry>
        <mesh filename="package://xarm_description/meshes/xarm6/visual/link3.stl"/>
      </geometry>
    </collision>
  </link>

  <!-- Joint 3 -->
  <joint name="joint3" type="revolute">
    <parent link="link2"/>
    <child link="link3"/>
    <origin xyz="0.0535 -0.2845 0" rpy="0 0 0"/>
    <axis xyz="0 0 1"/>
    <limit lower="-3.927" upper="0.19198" effort="32.0" velocity="3.14"/>
    <dynamics damping="1.0" friction="1.0"/>
  </joint>

  <!-- Link 4 -->
  <link name="link4">
    <inertial>
      <origin xyz="0 0 0" rpy="0 0 0" />
      <mass value="1.5" />
      <inertia
        ixx="0.01" ixy="0" ixz="0"
        iyy="0.01" iyz="0" izz="0.01" />
    </inertial>
    <visual>
      <origin xyz="0 0 0" rpy="0 0 0"/>
      <geometry>
        <mesh filename="package://xarm_description/meshes/xarm6/visual/link4.stl"/>
      </geometry>
      <material name="White"/>
    </visual>
    <collision>
      <origin xyz="0 0 0" rpy="0 0 0"/>
      <geometry>
        <mesh filename="package://xarm_description/meshes/xarm6/visual/link4.stl"/>
      </geometry>
    </collision>
  </link>

  <!-- Joint 4 -->
  <joint name="joint4" type="revolute">
    <parent link="link3"/>
    <child link="link4"/>
    <origin xyz="0.0775 0.3425 0" rpy="-1.5708 0 0"/>
    <axis xyz="0 0 1"/>
    <limit lower="-6.28319" upper="6.28319" effort="32.0" velocity="3.14"/>
    <dynamics damping="1.0" friction="1.0"/>
  </joint>

  <!-- Link 5 -->
  <link name="link5">
    <inertial>
      <origin xyz="0 0 0" rpy="0 0 0" />
      <mass value="1.5" />
      <inertia
        ixx="0.01" ixy="0" ixz="0"
        iyy="0.01" iyz="0" izz="0.01" />
    </inertial>
    <visual>
      <origin xyz="0 0 0" rpy="0 0 0"/>
      <geometry>
        <mesh filename="package://xarm_description/meshes/xarm6/visual/link5.stl"/>
      </geometry>
      <material name="White"/>
    </visual>
    <collision>
      <origin xyz="0 0 0" rpy="0 0 0"/>
      <geometry>
        <mesh filename="package://xarm_description/meshes/xarm6/visual/link5.stl"/>
      </geometry>
    </collision>
  </link>

  <!-- Joint 5 -->
  <joint name="joint5" type="revolute">
    <parent link="link4"/>
    <child link="link5"/>
    <origin xyz="0 0 0" rpy="-1.5708 0 0"/>
    <axis xyz="0 0 1"/>
    <limit lower="-1.69297" upper="3.14159" effort="32.0" velocity="3.14"/>
    <dynamics damping="1.0" friction="1.0"/>
  </joint>

  <!-- Link 6 -->
  <link name="link6">
    <inertial>
      <origin xyz="0 0 0" rpy="0 0 0" />
      <mass value="1.0" />
      <inertia
        ixx="0.005" ixy="0" ixz="0"
        iyy="0.005" iyz="0" izz="0.005" />
    </inertial>
    <visual>
      <origin xyz="0 0 0" rpy="0 0 0"/>
      <geometry>
        <mesh filename="package://xarm_description/meshes/xarm6/visual/link6.stl"/>
      </geometry>
      <material name="Silver"/>
    </visual>
    <collision>
      <origin xyz="0 0 0" rpy="0 0 0"/>
      <geometry>
        <mesh filename="package://xarm_description/meshes/end_tool/collision/end_tool.stl"/>
      </geometry>
    </collision>
  </link>

  <!-- Joint 6 -->
  <joint name="joint6" type="revolute">
    <parent link="link5"/>
    <child link="link6"/>
    <origin xyz="0.076 0.097 0" rpy="-1.5708 0 0"/>
    <axis xyz="0 0 1"/>
    <limit lower="-6.28319" upper="6.28319" effort="20.0" velocity="3.14"/>
    <dynamics damping="1.0" friction="1.0"/>
  </joint>

  <!-- End Effector -->
  <link name="link_eef" />
  <joint name="joint_eef" type="fixed">
    <origin xyz="0 0 0" rpy="0 0 0" />
    <parent link="link6" />
    <child link="link_eef" />
  </joint>
</robot>
